Workbook

Sheet PRODUCTOS
B2: ROTACIÓN PRODUCTOS | E2: ROTACIÓN BODEGA TU PIEL ENERO
E3: Fecha Reporte: | H3: =C7 -> 46072
B4: REPORTE PRODUCTOS FEBRERO | E4: CONTROL BOTOX | H4: CONTROL RADIESSE
B5: DÍAS HÁB MES | C5: ='BALANCE PPTO'!E15 -> 24 | E5: Meta Febrero | F5: 5000 | H5: Meta Febrero | I5: 20
B6: DÍAS EJECT | C6: ='TABLERO Y AGENDA'!P3 -> 16 | E6: Vendidos | F6: =F22 -> 2328 | H6: Vendidos | I6: =I22 -> 3
B7: FECHA | C7: ='TABLERO Y AGENDA'!N3 -> 46072 | E7: Faltan | F7: =F5-F6 -> 2672 | H7: Faltan | I7: =I5-I6 -> 17
B8: META FEBRERO | C8: 60000000 | E8: CONTROL HARMONYCA | H8: CONTROL BELOTERO
B9: META DÍA | C9: =+C8/C5 -> 2500000 | E9: Meta Febrero | F9: 20 | H9: AH Balance | I9: 10
B10: VENTA ESPERADA | C10: =+(C8/C5)*C6 -> 40000000 | E10: Vendidos | F10: =F26 -> 3 | H10: AH Intense | I10: 20
B11: FACTURADO FEB | C11: 47404171 | E11: Faltan | F11: =F9-F10 -> 17 | H11: AH Volume | I11: 4
B12: VENTA ADICIONAL | C12: =+C11-C10 -> 7404171 | E12: CONTROL SKINVIVE | H12: AH Revive | I12: 3
B13: FALTA X CUMPLIR | C13: =C8-C11 -> 12595829 | E13: Meta Febrero | F13: 17 | H13: Meta Febrero | I13: =SUM(I9:I12) -> 37
B14: % ESPERADO | C14: =C10/C8 -> 0.66666667 | E14: Vendidos | F14: =F30 -> 15 | H14: Vendidos | I14: =I30 -> 17 | N14: f
B15: CUMPLIMIENTO | C15: =+C11/C8 -> 0.79006952 | E15: Faltan | F15: =F13-F14 -> 2 | H15: Faltan | I15: =I13-I14 -> 20
E19: CONTROL BOTOX | H19: CONTROL RADIESSE
E20: Meta Febrero | F20: 14359 | H20: Meta Febrero | I20: 49
E21: Disponibles Hoy | F21: 12031 | H21: Disponibles Hoy | I21: 46
E22: Unidades Botox Vendidas | F22: =F20-F21 -> 2328 | H22: Radiesse Vendidos | I22: =I20-I21 -> 3
E23: CONTROL HARMONYCA | H23: CONTROL BELOTERO
E24: Meta Febrero | F24: 89 | H24: AH Balance | I24: 40
E25: Disponibles Hoy | F25: 86 | H25: AH Intense | I25: 64
E26: Hca Vendidos | F26: =F24-F25 -> 3 | H26: AH Volume | I26: 19
E27: CONTROL SKINVIVE | H27: AH Revive | I27: 3
E28: Meta Febrero | F28: 17 | H28: Meta Febrero | I28: 143
E29: Disponibles Hoy | F29: 2 | H29: Disponibles Hoy | I29: =I24+I25+I26+I27 -> 126
E30: Skinvive Vendidos | F30: =F28-F29 -> 15 | H30: AH Belotero Vendidos | I30: =I28-I29 -> 17

Sheet PPTO TP LOUNGE
M4: % ESP | O4: REPORTE GENERAL
M5: =(E5+J5)/F5 -> #DIV/0! | O5: ='PPTO TP LOUNGE'!P18 -> 46072
M6: =(E6+J6)/F6 -> #DIV/0!
R7: EQUIPO TP PM
M8: =(E8+J8)/F8 -> #DIV/0! | O8: % ESPERADO AL DÍA | P8: % REAL AL DÍA
M9: =(E10+J10)/F10 -> #DIV/0! | O9: ='PPTO TP LOUNGE'!P31 -> 0.66666667 | P9: =P32 -> 0.65254681
M10: =(E11+J11)/F11 -> #DIV/0! | O10: =O33 -> % DIFERENCIA | P10: NOS FALTA VENDER
M11: =(E17+J17)/F17 -> 1.42275 | O11: =P33 -> -0.014119858 | P11: =100%-P9 -> 0.34745319
M12: =(E18+J18)/F18 -> 0.42375
M13: =(E19+J19)/F19 -> 1.0035 | O13: =P25 -> 0.87602021 | P13: =(P19*P25) -> 411729500 | Q13: QUITAR
B14: CONTROLADOR DE PRESUPUESTOS TP LOUNGE
M15: =(E20+J20)/F20 -> 0.164375 | O15: ESTRATEGIA DICIEMBRE
B16: ='TABLERO Y AGENDA'!N3 -> 46072 | C16: PERSONAL | D16: # ATENCIONES | E16: $ VENTA | F16: PRESUPUESTO | G16: VENTA | H16: VENTA IDEAL | I16: PROYECCIÓN % | J16: PROYECCIÓN $ | K16: PENDIENTE % | L16: PENDIENTE $ | O16: DÍAS HÁB MES | P16: ='BALANCE PPTO'!E15 -> 24
B17: TP LOUNGE | C17: LUISA FERNANDA CORREA HERNANDEZ | D17: =+COUNTIF(INFO.RENTABILIDAD!$F:F,C17) -> 17 | E17: =SUMIFS(INFO.RENTABILIDAD!$L$1:$L$15000,INFO.RENTABILIDAD!$F$1:$F$15000,C17,INFO.RENTABILIDAD!$W$1:$W$15000,"SI") -> 2340000 | F17: 8000000 | G17: =E17/F17 -> 0.2925 | H17: =(F17/$P$16)*$P$17 -> 5333333.3 | I17: =J17/F17 -> 1.13025 | J17: =SUMIF(INFO.PROYECCIÓN!$F:$F,C17,INFO.PROYECCIÓN!L:L) -> 9042000 | K17: =(L17/F17) -> 0.42275 | L17: =-(+F17-E17-J17) -> 3382000 | O17: DÍAS EJECT | P17: ='BALANCE PPTO'!E16 -> 16
C18: YANED FAYSURI RESTREPO | D18: =+COUNTIF(INFO.RENTABILIDAD!$F:F,C18) -> 32 | E18: =SUMIFS(INFO.RENTABILIDAD!$L$1:$L$15000,INFO.RENTABILIDAD!$F$1:$F$15000,C18,INFO.RENTABILIDAD!$W$1:$W$15000,"SI") -> 3390000 | F18: 8000000 | G18: =E18/F18 -> 0.42375 | H18: =(F18/$P$16)*$P$17 -> 5333333.3 | I18: =J18/F18 -> 0 | J18: =SUMIF(INFO.PROYECCIÓN!$F:$F,C18,INFO.PROYECCIÓN!L:L) -> 0 | K18: =(L18/F18) -> -0.57625 | L18: =-(+F18-E18-J18) -> -4610000 | O18: FECHA | P18: ='TABLERO Y AGENDA'!N3 -> 46072
C19: LINDA ELIANA AROCA LONDOÑO | D19: =+COUNTIF(INFO.RENTABILIDAD!$F:F,C19) -> 46 | E19: =SUMIFS(INFO.RENTABILIDAD!$L$1:$L$15000,INFO.RENTABILIDAD!$F$1:$F$15000,C19,INFO.RENTABILIDAD!$W$1:$W$15000,"SI") -> 6916000 | F19: 8000000 | G19: =E19/F19 -> 0.8645 | H19: =(F19/$P$16)*$P$17 -> 5333333.3 | I19: =J19/F19 -> 0.139 | J19: =SUMIF(INFO.PROYECCIÓN!$F:$F,C19,INFO.PROYECCIÓN!L:L) -> 1112000 | K19: =(L19/F19) -> 0.0035 | L19: =-(+F19-E19-J19) -> 28000 | O19: META DICIEMBRE | P19: 470000000
C20: ISABELLA GONZALEZ MEJIA | D20: =+COUNTIF(INFO.RENTABILIDAD!$F:F,C20) -> 9 | E20: =SUMIFS(INFO.RENTABILIDAD!$L$1:$L$15000,INFO.RENTABILIDAD!$F$1:$F$15000,C20,INFO.RENTABILIDAD!$W$1:$W$15000,"SI") -> 1315000 | F20: 8000000 | G20: =E20/F20 -> 0.164375 | H20: =(F20/$P$16)*$P$17 -> 5333333.3 | I20: =J20/F20 -> 0 | J20: =SUMIF(INFO.PROYECCIÓN!$F:$F,C20,INFO.PROYECCIÓN!L:L) -> 0 | K20: =(L20/F20) -> -0.835625 | L20: =-(+F20-E20-J20) -> -6685000 | O20: VENTA ESPERADA DIC | P20: =P34*P17 -> 3.1333333e+08
C21: KAREN LORENA AMARIS GARCES | D21: =+COUNTIF(INFO.RENTABILIDAD!$F:F,C21) -> 29 | E21: =SUMIFS(INFO.RENTABILIDAD!$L$1:$L$15000,INFO.RENTABILIDAD!$F$1:$F$15000,C21,INFO.RENTABILIDAD!$W$1:$W$15000,"SI") -> 4946000 | F21: 8000000 | G21: =E21/F21 -> 0.61825 | H21: =(F21/$P$16)*$P$17 -> 5333333.3 | I21: =J21/F21 -> 0.055 | J21: =SUMIF(INFO.PROYECCIÓN!$F:$F,C21,INFO.PROYECCIÓN!L:L) -> 440000 | K21: =(L21/F21) -> -0.32675 | L21: =-(+F21-E21-J21) -> -2614000 | O21: FACTURADO DIC | P21: ='REPORTE X DÍAS'!K16 -> 306697000
D22: Total TP Lounge: | E22: =SUM(E17:E21) -> 18907000 | F22: =SUM(F17:F21) -> 40000000 | H22: =SUM(H17:H21) -> 26666667 | O22: PROYECCIÓN DIC | P22: =SUM(INFO.PROYECCIÓN!L:L) -> 105032500
O23: FALTA X CUMPLIR | P23: =P19-P22-P21 -> 58270500
O24: RESULTADO ESP | P24: =P21+P22 -> 411729500
O25: % RESULTADO ESP | P25: =P24/P19 -> 0.87602021
O27: =O10 -> % DIFERENCIA | P27: =O11 -> -0.014119858
O30: NO INCLUIR EN EL INFORME POR FA!
O31: % AL DÍA | P31: =P17/P16 -> 0.66666667
O32: % REAL CUM | P32: =P21/P19 -> 0.65254681
O33: % DIFERENCIA | P33: =P32-P31 -> -0.014119858
O34: META DIARIA | P34: =P19/P16 -> 19583333 | Q34: =P34*22 -> 4.3083333e+08
O35: OTRAS VENTAS | P35: =P21-(E5+E6+E8+E10+E11+E17+E18+E19) -> 294051000
O36: FALTA X CUMPLIR | P36: ='REPORTE X DÍAS'!K20 -> 108270500
O37: CARTERA OCT | P37: ='REPORTE X DÍAS'!K18 -> 0
O38: ANTICIPOS OCT | P38: ='REPORTE X DÍAS'!K19 -> 6687000

Sheet PPTO TP C.E
B2: CONTROLADOR DE PRESUPUESTOS ESPECIALISTAS
B4: ='TABLERO Y AGENDA'!N3 -> 46072 | C4: PERSONAL | D4: # ATENCIONES | E4: $ VENTA | F4: PRESUPUESTO | G4: % VENTA | H4: VENTA IDEAL | I4: PROYECCIÓN % | J4: PROYECCIÓN $ | K4: PENDIENTE % | L4: PENDIENTE $ | M4: % ESP | O4: REPORTE GENERAL
B5: DERMATOLOGÍA | C5: LUISA HERNANDEZ TEJADA | D5: =+COUNTIF(INFO.RENTABILIDAD!$F:F,C5) -> 153 | E5: =SUMIFS(INFO.RENTABILIDAD!$L$1:$L$15000,INFO.RENTABILIDAD!$F$1:$F$15000,C5,INFO.RENTABILIDAD!$W$1:$W$15000,"SI") -> 59554500 | F5: 80000000 | G5: =E5/F5 -> 0.74443125 | H5: =(F5/$P$17)*$P$18 -> 53333333 | I5: =J5/F5 -> 0.249125 | J5: =SUMIF(INFO.PROYECCIÓN!$F:$F,C5,INFO.PROYECCIÓN!L:L) -> 19930000 | K5: =(L5/F5) -> -0.00644375 | L5: =-(+F5-E5-J5) -> -515500 | M5: =(E5+J5)/F5 -> 0.99355625 | O5: ='PPTO TP C.E'!P19 -> 46072
C6: DANIELA ASTAROT SALAZAR URIBE | D6: =+COUNTIF(INFO.RENTABILIDAD!$F:F,C6) -> 157 | E6: =SUMIFS(INFO.RENTABILIDAD!$L$1:$L$15000,INFO.RENTABILIDAD!$F$1:$F$15000,C6,INFO.RENTABILIDAD!$W$1:$W$15000,"SI") -> 78240000 | F6: 110000000 | G6: =E6/F6 -> 0.71127273 | H6: =(F6/$P$17)*$P$18 -> 73333333 | I6: =J6/F6 -> 0.28202273 | J6: =SUMIF(INFO.PROYECCIÓN!$F:$F,C6,INFO.PROYECCIÓN!L:L) -> 31022500 | K6: =(L6/F6) -> -0.0067045455 | L6: =-(+F6-E6-J6) -> -737500 | M6: =(E6+J6)/F6 -> 0.99329545
C7: JURANY SANCHEZ | D7: =+COUNTIF(INFO.RENTABILIDAD!$F:F,C7) -> 144 | E7: =SUMIFS(INFO.RENTABILIDAD!$L$1:$L$15000,INFO.RENTABILIDAD!$F$1:$F$15000,C7,INFO.RENTABILIDAD!$W$1:$W$15000,"SI") -> 60705000 | F7: 110000000 | G7: =E7/F7 -> 0.55186364 | H7: =(F7/$P$17)*$P$18 -> 73333333 | I7: =J7/F7 -> 0.20827273 | J7: =SUMIF(INFO.PROYECCIÓN!$F:$F,C7,INFO.PROYECCIÓN!L:L) -> 22910000 | K7: =(L7/F7) -> -0.23986364 | L7: =-(+F7-E7-J7) -> -26385000 | R7: EQUIPO TP PM
C8: PAULA ANDREA ARISTIZABAL DIAZ | D8: =+COUNTIF(INFO.RENTABILIDAD!$F:F,C8) -> 107 | E8: =SUMIFS(INFO.RENTABILIDAD!$L$1:$L$15000,INFO.RENTABILIDAD!$F$1:$F$15000,C8,INFO.RENTABILIDAD!$W$1:$W$15000,"SI") -> 22214000 | F8: 30000000 | G8: =E8/F8 -> 0.74046667 | H8: =(F8/$P$17)*$P$18 -> 20000000 | I8: =J8/F8 -> 0.079533333 | J8: =SUMIF(INFO.PROYECCIÓN!$F:$F,C8,INFO.PROYECCIÓN!L:L) -> 2386000 | K8: =(L8/F8) -> -0.18 | L8: =-(+F8-E8-J8) -> -5400000 | M8: =(E8+J8)/F8 -> 0.82 | O8: % ESPERADO AL DÍA | P8: % REAL AL DÍA
C9: DAVID CHALARCA CANAS | D9: =+COUNTIF(INFO.RENTABILIDAD!$F:F,C9) -> 100 | E9: =SUMIFS(INFO.RENTABILIDAD!$L$1:$L$15000,INFO.RENTABILIDAD!$F$1:$F$15000,C9,INFO.RENTABILIDAD!$W$1:$W$15000,"SI") -> 29544500 | F9: 70000000 | G9: =E9/F9 -> 0.42206429 | H9: =(F9/$P$17)*$P$18 -> 46666667 | I9: =J9/F9 -> 0.091571429 | J9: =SUMIF(INFO.PROYECCIÓN!$F:$F,C9,INFO.PROYECCIÓN!L:L) -> 6410000 | K9: =(L9/F9) -> -0.48636429 | L9: =-(+F9-E9-J9) -> -34045500 | M9: =(E11+J11)/F11 -> 0.663375 | O9: ='PPTO TP C.E'!P32 -> 0.66666667 | P9: =P33 -> 0.65254681
D10: Total Derma: | E10: =SUM(E5:E9) -> 250258000 | F10: =SUM(F5:F9) -> 400000000 | H10: =(F10/$P$17)*$P$18 -> 2.6666667e+08
B11: MED ESTÉTICA | C11: MARIA CAMILA ZULUAGA ALVAREZ | D11: =+COUNTIF(INFO.RENTABILIDAD!$F:F,C11) -> 26 | E11: =SUMIFS(INFO.RENTABILIDAD!$L$1:$L$15000,INFO.RENTABILIDAD!$F$1:$F$15000,C11,INFO.RENTABILIDAD!$W$1:$W$15000,"SI") -> 16275000 | F11: 40000000 | G11: =E11/F11 -> 0.406875 | H11: =(F11/$P$17)*$P$18 -> 26666667 | I11: =J11/F11 -> 0.2565 | J11: =SUMIF(INFO.PROYECCIÓN!$F:$F,C11,INFO.PROYECCIÓN!L:L) -> 10260000 | K11: =(L11/F11) -> -0.336625 | L11: =-(+F11-E11-J11) -> -13465000 | M11: =(E12+J12)/F12 -> 0.565925 | O11: =O34 -> % DIFERENCIA | P11: NOS FALTA VENDER
C12: STEPHANIA LAGUADO GONZALEZ | D12: =+COUNTIF(INFO.RENTABILIDAD!$F:F,C12) -> 29 | E12: =SUMIFS(INFO.RENTABILIDAD!$L$1:$L$15000,INFO.RENTABILIDAD!$F$1:$F$15000,C12,INFO.RENTABILIDAD!$W$1:$W$15000,"SI") -> 21257000 | F12: 40000000 | G12: =E12/F12 -> 0.531425 | H12: =(F12/$P$17)*$P$18 -> 26666667 | I12: =J12/F12 -> 0.0345 | J12: =SUMIF(INFO.PROYECCIÓN!$F:$F,C12,INFO.PROYECCIÓN!L:L) -> 1380000 | K12: =(L12/F12) -> -0.434075 | L12: =-(+F12-E12-J12) -> -17363000 | M12: =(E18+J18)/F18 -> #DIV/0! | O12: =P34 -> -0.014119858 | P12: =100%-P9 -> 0.34745319
D13: Total Med Estética: | E13: =SUM(E11:E12) -> 37532000 | F13: =SUM(F11:F12) -> 80000000 | H13: =SUM(H11:H12) -> 53333333
M14: =(E20+J20)/F20 -> #DIV/0! | O14: =P26 -> 0.87602021 | P14: =(P20*P26) -> 411729500 | Q14: QUITAR
M16: =(E21+J21)/F21 -> #DIV/0! | O16: ESTRATEGIA DICIEMBRE
O17: DÍAS HÁB MES | P17: ='BALANCE PPTO'!E15 -> 24
O18: DÍAS EJECT | P18: ='BALANCE PPTO'!E16 -> 16
O19: FECHA | P19: ='TABLERO Y AGENDA'!N3 -> 46072
O20: META DICIEMBRE | P20: 470000000
O21: VENTA ESPERADA DIC | P21: =P35*P18 -> 3.1333333e+08
O22: FACTURADO DIC | P22: ='REPORTE X DÍAS'!K16 -> 306697000
O23: PROYECCIÓN DIC | P23: =SUM(INFO.PROYECCIÓN!L:L) -> 105032500
O24: FALTA X CUMPLIR | P24: =P20-P23-P22 -> 58270500
O25: RESULTADO ESP | P25: =P22+P23 -> 411729500
O26: % RESULTADO ESP | P26: =P25/P20 -> 0.87602021
O28: =O11 -> % DIFERENCIA | P28: =O12 -> -0.014119858
O31: NO INCLUIR EN EL INFORME POR FA!
O32: % AL DÍA | P32: =P18/P17 -> 0.66666667
O33: % REAL CUM | P33: =P22/P20 -> 0.65254681
O34: % DIFERENCIA | P34: =P33-P32 -> -0.014119858
O35: META DIARIA | P35: =P20/P17 -> 19583333 | Q35: =P35*22 -> 4.3083333e+08
O36: OTRAS VENTAS | P36: =P22-(E5+E6+E8+E11+E12+E18+E19+E20) -> 109156500
O37: FALTA X CUMPLIR | P37: ='REPORTE X DÍAS'!K20 -> 108270500
O38: CARTERA OCT | P38: ='REPORTE X DÍAS'!K18 -> 0
O39: ANTICIPOS OCT | P39: ='REPORTE X DÍAS'!K19 -> 6687000

Sheet BALANCE PPTO
B4: % ESP | D4: REPORTE GENERAL
B5: =(#REF!+#REF!)/#REF! -> #REF! | D5: ='BALANCE PPTO'!E17 -> 46072
B6: =(#REF!+#REF!)/#REF! -> #REF!
I7: Meta Tu Piel Centro Especializado
B8: =(#REF!+#REF!)/#REF! -> #REF! | D8: % ESPERADO AL DÍA | E8: % REAL AL DÍA
B9: =(#REF!+#REF!)/#REF! -> #REF! | D9: ='BALANCE PPTO'!E30 -> 0.66666667 | E9: =E31 -> 0.58980192
B10: =(#REF!+#REF!)/#REF! -> #REF! | D10: =D32 -> % DIFERENCIA | E10: NOS FALTA VENDER
B11: =(#REF!+#REF!)/#REF! -> #REF! | D11: =E32 -> -0.076864744 | E11: =100%-E9 -> 0.41019808
B12: =(#REF!+#REF!)/#REF! -> #REF!
B14: =(#REF!+#REF!)/#REF! -> #REF! | D14: ESTRATEGIA FEBRERO
D15: DÍAS HÁB MES | E15: 24 | G15: Unidad de Negocio | H15: Venta | I15: Meta | J15: Faltaría | L15: Balance Meta
D16: DÍAS EJECT | E16: ='TABLERO Y AGENDA'!P3 -> 16 | G16: Tu Piel Derma | H16: ='PPTO TP C.E'!E10 -> 250258000 | I16: ='PPTO TP C.E'!F10 -> 400000000 | J16: =H16-I16 -> -149742000 | L16: Meta Global | M16: =I20 -> 580000000
D17: FECHA | E17: ='TABLERO Y AGENDA'!N3 -> 46072 | G17: Tu Piel Medicina Estética | H17: ='PPTO TP C.E'!E13 -> 37532000 | I17: 80000000 | J17: =H17-I17 -> -42468000 | L17: Ventas | M17: =H20 -> 354101171
D18: META ENERO | E18: 520000000 | G18: TP Lounge | H18: ='PPTO TP LOUNGE'!E22 -> 18907000 | I18: 40000000 | J18: =H18-I18 -> -21093000 | L18: Agendamiento | M18: =E21 -> 105032500
D19: VENTA ESPERADA FEB | E19: =E33*E16 -> 3.4666667e+08 | G19: Productos | H19: =PRODUCTOS!C11 -> 47404171 | I19: 60000000 | J19: =H19-I19 -> -12595829 | L19: Falta | M19: =M18+M17-M16 -> -120866329
D20: FACTURADO FEB | E20: ='REPORTE X DÍAS'!K16 -> 306697000 | G20: Total | H20: =SUM(H16:H19) -> 354101171 | I20: =SUM(I16:I19) -> 580000000
D21: PROYECCIÓN FEB | E21: =SUM(INFO.PROYECCIÓN!L:L) -> 105032500 | H21: =H20*3 -> 1062303513
D22: FALTA X CUMPLIR | E22: =E18-E21-E20 -> 108270500
D23: RESULTADO ESP | E23: =E20+E21 -> 411729500 | G23: =+H20/21 -> 16861961
D24: % RESULTADO ESP | E24: =E23/E18 -> 0.7917875
D26: =D10 -> % DIFERENCIA | E26: =D11 -> -0.076864744
D29: NO INCLUIR EN EL INFORME POR FA!
D30: % AL DÍA | E30: =E16/E15 -> 0.66666667
D31: % REAL CUM | E31: =E20/E18 -> 0.58980192
D32: % DIFERENCIA | E32: =E31-E30 -> -0.076864744
D33: META DIARIA | E33: =E18/E15 -> 21666667 | F33: =E33*22 -> 4.7666667e+08
D34: OTRAS VENTAS | E34: =E20-(#REF!+#REF!+#REF!+#REF!+#REF!+#REF!+#REF!+#REF!) -> #REF!
D35: FALTA X CUMPLIR | E35: ='REPORTE X DÍAS'!K20 -> 108270500
D36: CARTERA OCT | E36: ='REPORTE X DÍAS'!K18 -> 0
D37: ANTICIPOS OCT | E37: ='REPORTE X DÍAS'!K19 -> 6687000
D42: Meta Ventas | E42: Valor $
D43: Tu Piel Centro Especializado | E43: 420000000
D44: Tu Piel Lounge | E44: 40000000
D45: Venta de Producto | E45: 55000000

Sheet INFO.PROYECCIÓN
A1: # Atención | B1: # Registro | C1: Fecha | D1: Doc. Paciente | E1: Nombre Paciente | F1: Personal Atiende | G1: Código Cups | H1: Cups | I1: Sub Categoria | J1: Categoria | K1: Dispositivo | L1: Vlr | M1: Vlr Comisiones | N1: Vlr Insumos | O1: Costo Adicional | P1: Rentabilidad Insumos | Q1: Rentabilidad Equipos | R1: Rentabilidad Ips | S1: Rentabilidad Total | T1: Rentabilidad Porcentaje | U1: Pendiente Registrar | V1: Fecha Facturación | W1: Pagado este mes | X1: Procedencia / Recomendacion | Y1: Edad del paciente | Z1: Numero Factura
A2: 24079 | B2: 6805 | C2: 46073 | D2: CC 1017206567 | E2: MARIA ALEJANDRA RAMIREZ | F2: LUISA FERNANDA CORREA HERNANDEZ | G2: DL0011 | H2: COMBO 7 (DEPILACIÓN ZONA MINI + MEDIANA) | I2: DEPILACION - COSMETOLOGÍA | J2: COSMETOLOGÍA | K2: 1050 DEPILACIÓN REMOVALL | L2: 130000 | M2: 22100 | N2: 0 | O2: 0 | P2: 0 | Q2: 0 | R2: 107900 | S2: 107900 | T2: 0.83 | U2: SI | W2: SIN PAGO | X2: AMIG@ | Y2: 33
A3: 28314 | B3: 13524 | C3: 46074 | D3: CC 1033489106 | E3: JUAN JOSE ARBOLEDA GARCIA | F3: JURANY SANCHEZ | G3: 890242 | H3: CONSULTA DE PRIMERA VEZ POR MEDICINA ESPECIALIZADA -DERMATOL | I3: CONSULTA PRIMERA VEZ - CONSULTA | J3: CONSULTA | L3: 230000 | M3: 115000 | N3: 0 | O3: 0 | P3: 0 | Q3: 0 | R3: 115000 | S3: 115000 | T3: 0.5 | U3: SI | W3: SIN PAGO | X3: AMIG@ | Y3: 0
A4: 30702 | B4: 17553 | C4: 46080 | D4: CC 1049611021 | E4: YESICA PAOLA ARIZA MORA | F4: LUISA HERNANDEZ TEJADA | G4: LP0001 | H4: LONGPULSE - MELASMA COMPONENTE VASCULAR + PIGMENTARIO - PASO 1/2 | I4: LONGPULSE - PROCEDIMIENTOS | J4: PROCEDIMIENTOS | K4: 60 LONGPULSE | L4: 150000 | M4: 75000 | N4: 0 | O4: 0 | P4: 0 | Q4: 0 | R4: 75000 | S4: 75000 | T4: 0.5 | U4: SI | W4: SIN PAGO | X4: INSTAGRAM | Y4: 37
A5: 30702 | B5: 17554 | C5: 46080 | D5: CC 1049611021 | E5: YESICA PAOLA ARIZA MORA | F5: LUISA HERNANDEZ TEJADA | G5: HP0001 | H5: HANDPICO - MELASMA COMPONENTE PIGMENTARIO - PASO 2/2 | I5: HANDPICO - PROCEDIMIENTOS | J5: PROCEDIMIENTOS | K5: 60 LONGPULSE | L5: 450000 | M5: 225000 | N5: 0 | O5: 0 | P5: 0 | Q5: 0 | R5: 225000 | S5: 225000 | T5: 0.5 | U5: SI | W5: SIN PAGO | X5: INSTAGRAM | Y5: 37
A6: 32356 | B6: 20091 | C6: 46077 | D6: CC 1192741542 | E6: LAURA VICTORIA LOPEZ HERNANDEZ | F6: JURANY SANCHEZ | G6: HP0008 | H6: HANDPICO - TATUAJE PEQUEÑO HASTA 3 CM | I6: HANDPICO - PROCEDIMIENTOS | J6: PROCEDIMIENTOS | K6: 1034 HANDPICO | L6: 540000 | M6: 264600 | N6: 0 | O6: 0 | P6: 0 | Q6: 0 | R6: 275400 | S6: 264600 | T6: 0.49 | U6: SI | V6: 2025-10-03 11:34:00 | W6: NO | X6: INSTAGRAM | Y6: 25 | Z6: FE10984
A7: 32370 | B7: 21321 | C7: 46076 | D7: CC 1007053639 | E7: SEBASTIAN VELEZ ZAPATA | F7: DANIELA ASTAROT SALAZAR URIBE | G7: 861401 | H7: INFILTRACION INTRALESIONAL 1-5 LESIONES | I7: PROCE DERMA - PROCEDIMIENTOS | J7: PROCEDIMIENTOS | L7: 250000 | M7: 125000 | N7: 0 | O7: 0 | P7: 0 | Q7: 0 | R7: 125000 | S7: 125000 | T7: Revisar insumos | U7: SI | W7: SIN PAGO | X7: PAGINA WEB | Y7: 23
A8: 33282 | B8: 21442 | C8: 46080 | D8: CC 1036643377 | E8: CAMILA PELAEZ USMA | F8: JURANY SANCHEZ | G8: PD0009 | H8: CICATRICES POST QUIRURGICAS 6-10 CMS - PRODEEP | I8: PRODEEP - PROCEDIMIENTOS | J8: PROCEDIMIENTOS | K8: 59 PRODEEP | L8: 500000 | M8: 250000 | N8: 0 | O8: 0 | P8: 0 | Q8: 0 | R8: 250000 | S8: 250000 | T8: 0.5 | U8: SI | W8: SIN PAGO | X8: INSTAGRAM | Y8: 33
A9: 33013 | B9: 21585 | C9: 46076 | D9: CC 1152683958 | E9: CAMILO OCHOA HERNANDEZ | F9: LUISA FERNANDA CORREA HERNANDEZ | G9: DL0001 | H9: DEPILACION ZONA PEQUEÑA (AXILAS, LINEA ALBA, MANOS) | I9: DEPILACION - COSMETOLOGÍA | J9: COSMETOLOGÍA | K9: 1050 DEPILACIÓN REMOVALL | L9: 57000 | M9: 9496.2 | N9: 0 | O9: 0 | P9: 0 | Q9: 0 | R9: 47503.8 | S9: 46363.8 | T9: 0.8134 | U9: SI | V9: 2025-11-08 13:59:00 | W9: NO | X9: AMIG@ | Y9: 34 | Z9: FE58
A10: 33776 | B10: 22262 | C10: 46074 | D10: TI 1064191165 | E10: JUAN CARLOS MARTINEZ BERRIO | F10: LUISA HERNANDEZ TEJADA | G10: 890302 | H10: CONSULTA DE CONTROL O DE SEGUIMIENTO POR MEDICINA ESPECIALIZADA > 1 MES | I10: CONSULTA CONTROL - CONSULTA | J10: CONSULTA | L10: 150000 | M10: 75000 | N10: 0 | O10: 0 | P10: 0 | Q10: 0 | R10: 75000 | S10: 75000 | T10: 0.5 | U10: SI | W10: SIN PAGO | X10: AMIG@ | Y10: 18
A11: 23034 | B11: 23194 | C11: 46079 | D11: CC 70753003 | E11: JUAN MANUEL RESTREPO | F11: JURANY SANCHEZ | G11: M00003 | H11: MESOTERAPIA PELO DUTASTERIDE | I11: MESOJECT - PROCEDIMIENTOS | J11: PROCEDIMIENTOS | L11: 450000 | M11: 225000 | N11: 0 | O11: 0 | P11: 0 | Q11: 0 | R11: 225000 | S11: 225000 | T11: Revisar insumos | U11: SI | W11: SIN PAGO | X11: AMIG@ | Y11: 50
A12: 34430 | B12: 23231 | C12: 46074 | D12: CC 43664001 | E12: MARGARITA ELENA MARIN MARIN | F12: LUISA HERNANDEZ TEJADA | G12: 868114 | H12: RESECCION BENIGNA < 1 CM SIN PATOLOGIA | I12: PROCE DERMA - PROCEDIMIENTOS | J12: PROCEDIMIENTOS | L12: 600000 | M12: 300000 | N12: 0 | O12: 0 | P12: 0 | Q12: 0 | R12: 300000 | S12: 300000 | T12: Revisar insumos | U12: SI | W12: SIN PAGO | X12: AMIG@ | Y12: 58
A13: 34430 | B13: 23289 | C13: 46074 | D13: CC 43664001 | E13: MARGARITA ELENA MARIN MARIN | F13: LUISA HERNANDEZ TEJADA | G13: PD0020 | H13: REJUVENECIMIENTO FACIAL + EXOSOMAS - PRODEEP | I13: PRODEEP - PROCEDIMIENTOS | J13: PROCEDIMIENTOS | K13: 59 PRODEEP | L13: 1800000 | M13: 900000 | N13: 0 | O13: 0 | P13: 0 | Q13: 0 | R13: 900000 | S13: 900000 | T13: Revisar insumos | U13: SI | W13: SIN PAGO | X13: AMIG@ | Y13: 58
A14: 34617 | B14: 23500 | C14: 46080 | D14: CC 1037598968 | E14: LADY YAMILEY BEDOYA CORREA | F14: LUISA HERNANDEZ TEJADA | G14: HP0001 | H14: HANDPICO - MELASMA COMPONENTE PIGMENTARIO - PASO 2/2 | I14: HANDPICO - PROCEDIMIENTOS | J14: PROCEDIMIENTOS | K14: 1034 HANDPICO | L14: 350000 | M14: 175000 | N14: 0 | O14: 0 | P14: 0 | Q14: 0 | R14: 175000 | S14: 175000 | T14: 0.5 | U14: SI | W14: SIN PAGO | X14: FACEBOOK | Y14: 37
A15: 33360 | B15: 23577 | C15: 46074 | D15: CC 1001535287 | E15: SANDRA MORALES MORALES | F15: LUISA HERNANDEZ TEJADA | G15: IP0001 | H15: IPL PROCEDIMIENTOS POR ZONA | I15: IPL-SQ - PROCEDIMIENTOS | J15: PROCEDIMIENTOS | K15: 43 IPL-SQ | L15: 400000 | M15: 200000 | N15: 0 | O15: 0 | P15: 0 | Q15: 0 | R15: 200000 | S15: 200000 | T15: 0.5 | U15: SI | W15: SIN PAGO | X15: INSTAGRAM | Y15: 23
A16: 34710 | B16: 23660 | C16: 46074 | D16: CC 1128329773 | E16: ADRIANA LUCIA SINNING OSORIO | F16: JURANY SANCHEZ | G16: 890242 | H16: CONSULTA DE PRIMERA VEZ POR MEDICINA ESPECIALIZADA -DERMATOL | I16: CONSULTA PRIMERA VEZ - CONSULTA | J16: CONSULTA | L16: 230000 | M16: 115000 | N16: 0 | O16: 0 | P16: 0 | Q16: 0 | R16: 115000 | S16: 115000 | T16: 0.5 | U16: SI | W16: SIN PAGO | X16: GOOGLE | Y16: 0
A17: 31859 | B17: 23739 | C17: 46080 | D17: CC 1042094737 | E17: ERICA LICETH GAVIRIA MEJIA | F17: DANIELA ASTAROT SALAZAR URIBE | G17: CM0017 | H17: COLOR MAX MELASMA - HIPERPIGMENTEACIONES | I17: COLOR MAX - PROCEDIMIENTOS | J17: PROCEDIMIENTOS | K17: NA LÁSER COLOR MAX | L17: 600000 | M17: 300000 | N17: 0 | O17: 0 | P17: 0 | Q17: 0 | R17: 300000 | S17: 300000 | T17: Revisar insumos | U17: SI | W17: SIN PAGO | X17: AMIG@ | Y17: 35
A18: 34302 | B18: 23908 | C18: 46076 | D18: CC 43255508 | E18: MARCELA VANEGAS GONZALEZ | F18: JURANY SANCHEZ | G18: 861415 | H18: APLICACIÓN BIOESTIMULADOR SCULPTRA | I18: INYECTABLES - PROCEDIMIENTOS | J18: PROCEDIMIENTOS | L18: 250000 | M18: 122500 | N18: 0 | O18: 0 | P18: 0 | Q18: 0 | R18: 127500 | S18: 122500 | T18: Revisar insumos | U18: SI | V18: 2026-01-26 13:54:00 | W18: NO | X18: AMIG@ | Y18: 44 | Z18: FE13689
A19: 33771 | B19: 24096 | C19: 46080 | D19: CC 1041328840 | E19: VERONICA ANDREA OCHOA SANCHEZ | F19: LUISA HERNANDEZ TEJADA | G19: IP0001 | H19: IPL PROCEDIMIENTOS POR ZONA | I19: IPL-SQ - PROCEDIMIENTOS | J19: PROCEDIMIENTOS | K19: 43 IPL-SQ | L19: 350000 | M19: 175000 | N19: 0 | O19: 0 | P19: 0 | Q19: 0 | R19: 175000 | S19: 175000 | T19: 0.5 | U19: SI | W19: SIN PAGO | X19: INSTAGRAM | Y19: 29
A20: 33771 | B20: 24097 | C20: 46080 | D20: CC 1041328840 | E20: VERONICA ANDREA OCHOA SANCHEZ | F20: LUISA HERNANDEZ TEJADA | G20: HP0001 | H20: HANDPICO - MELASMA COMPONENTE PIGMENTARIO - PASO 2/2 | I20: HANDPICO - PROCEDIMIENTOS | J20: PROCEDIMIENTOS | K20: 1034 HANDPICO | L20: 350000 | M20: 175000 | N20: 0 | O20: 0 | P20: 0 | Q20: 0 | R20: 175000 | S20: 175000 | T20: 0.5 | U20: SI | W20: SIN PAGO | X20: INSTAGRAM | Y20: 29
A21: 35029 | B21: 24100 | C21: 46073 | D21: CC 1000762846 | E21: RONALD DAVID MORELO GUARIN | F21: DANIELA ASTAROT SALAZAR URIBE | G21: 890242 | H21: CONSULTA DE PRIMERA VEZ POR MEDICINA ESPECIALIZADA -DERMATOL | I21: CONSULTA PRIMERA VEZ - CONSULTA | J21: CONSULTA | L21: 250000 | M21: 125000 | N21: 0 | O21: 0 | P21: 0 | Q21: 0 | R21: 125000 | S21: 125000 | T21: 0.5 | U21: SI | W21: SIN PAGO | X21: INSTAGRAM | Y21: 0
A22: 35071 | B22: 24152 | C22: 46081 | D22: RC 1036692000 | E22: DOMINIC CANO DUQUE | F22: PAULA ANDREA ARISTIZABAL DIAZ | G22: 890303 | H22: CONSULTA DE CONTROL - PROCEDIMIENTO | I22: CONSULTA CONTROL - CONSULTA | J22: CONSULTA | L22: 0 | M22: 0 | N22: 0 | O22: 0 | P22: 0 | Q22: 0 | R22: 0 | S22: 0 | T22: Revisar insumos | U22: SI | W22: SIN PAGO | X22: INSTAGRAM | Y22: 4
A23: 28033 | B23: 24170 | C23: 46073 | D23: CC 1037525219 | E23: MARIA JOSE ARROYAVE TABORDA | F23: LUISA FERNANDA CORREA HERNANDEZ | G23: DL0013 | H23: COMBO 8 (ZONA PEQUEÑA + ZONA MEDIANA) | I23: DEPILACION - COSMETOLOGÍA | J23: COSMETOLOGÍA | L23: 140000 | M23: 2800 | N23: 0 | O23: 0 | P23: 0 | Q23: 0 | R23: 137200 | S23: 137200 | T23: Revisar insumos | U23: SI | W23: SIN PAGO | X23: VITRINA | Y23: 26
A24: 35160 | B24: 24299 | C24: 46073 | D24: CC 1096253120 | E24: NAYBEHD AGUILAR JEREZ | F24: DANIELA ASTAROT SALAZAR URIBE | G24: LP0008 | H24: TRATAMIENTO DE ONICOMICOSIS - LONGPULSE | I24: LONGPULSE - PROCEDIMIENTOS | J24: PROCEDIMIENTOS | K24: 60 LONGPULSE | L24: 332500 | M24: 162925 | N24: 0 | O24: 0 | P24: 0 | Q24: 0 | R24: 169575 | S24: 162925 | T24: 0.49 | U24: SI | V24: 2026-01-06 19:15:00 | W24: NO | X24: INSTAGRAM | Y24: 26 | Z24: FE13231
A25: 35206 | B25: 24358 | C25: 46074 | D25: TI 1013463311 | E25: MARIANA RUIZ PEREIRA | F25: JURANY SANCHEZ | G25: M00011 | H25: FOTOAGE | I25: FOTOAGE - PROCEDIMIENTOS | J25: PROCEDIMIENTOS | K25: A123 DISPOSITIVO FOTOAGE | L25: 650000 | M25: 325000 | N25: 0 | O25: 0 | P25: 0 | Q25: 0 | R25: 325000 | S25: 325000 | T25: Revisar insumos | U25: SI | W25: SIN PAGO | X25: GOOGLE | Y25: 15
A26: 35135 | B26: 24388 | C26: 46077 | D26: CC 1048045744 | E26: KELLY YISELA OLARTE MEJIA | F26: DANIELA ASTAROT SALAZAR URIBE | G26: 868116 | H26: SUBCISION | I26: PROCE DERMA - PROCEDIMIENTOS | J26: PROCEDIMIENTOS | L26: 200000 | M26: 100000 | N26: 0 | O26: 0 | P26: 0 | Q26: 0 | R26: 100000 | S26: 100000 | T26: Revisar insumos | U26: SI | W26: SIN PAGO | X26: INSTAGRAM | Y26: 31
A27: 35135 | B27: 24389 | C27: 46077 | D27: CC 1048045744 | E27: KELLY YISELA OLARTE MEJIA | F27: DANIELA ASTAROT SALAZAR URIBE | G27: LC0001 | H27: CO2 CICATRICES ACNE CARA | I27: LASER Co2 - PROCEDIMIENTOS | J27: PROCEDIMIENTOS | K27: NA LÁSER IBLAZE (CO2) | L27: 1000000 | M27: 500000 | N27: 0 | O27: 0 | P27: 0 | Q27: 0 | R27: 500000 | S27: 500000 | T27: Revisar insumos | U27: SI | W27: SIN PAGO | X27: INSTAGRAM | Y27: 31
A28: 27318 | B28: 24515 | C28: 46080 | D28: CC 43182047 | E28: SANDRA VIVIANA BOTERO SERNA | F28: LUISA HERNANDEZ TEJADA | G28: LC0004 | H28: CO2 REJUVENICIMIENTO FACIAL | I28: LASER Co2 - PROCEDIMIENTOS | J28: PROCEDIMIENTOS | K28: NA LÁSER IBLAZE (CO2) | L28: 800000 | M28: 400000 | N28: 0 | O28: 0 | P28: 0 | Q28: 0 | R28: 400000 | S28: 400000 | T28: 0.5 | U28: SI | W28: SIN PAGO | X28: VITRINA | Y28: 41
A29: 35344 | B29: 24574 | C29: 46074 | D29: CC 1152218205 | E29: SARA ISABEL BRICEÑO MARIN | F29: LUISA HERNANDEZ TEJADA | G29: 890303 | H29: CONSULTA DE CONTROL - PROCEDIMIENTO | I29: CONSULTA CONTROL - CONSULTA | J29: CONSULTA | L29: 0 | M29: 0 | N29: 0 | O29: 0 | P29: 0 | Q29: 0 | R29: 0 | S29: 0 | T29: Revisar insumos | U29: SI | W29: SIN PAGO | X29: INSTAGRAM | Y29: 28
A30: 35421 | B30: 24709 | C30: 46078 | D30: CC 1000406864 | E30: JHON STEVEN SCHNAIDER ARISTIZABAL | F30: PAULA ANDREA ARISTIZABAL DIAZ | G30: 890303 | H30: CONSULTA DE CONTROL O DE SEGUIMIENTO POR ESPECIALISTA EN DERMATOLOGÍA < 1 MES | I30: PROCE DERMA - PROCEDIMIENTOS | J30: PROCEDIMIENTOS | L30: 0 | M30: 0 | N30: 0 | O30: 0 | P30: 0 | Q30: 0 | R30: 0 | S30: 0 | T30: 0 | U30: SI | W30: SIN PAGO | X30: INSTAGRAM | Y30: 26
A31: 35425 | B31: 24719 | C31: 46079 | D31: CC 1027740425 | E31: MANUELA POSADA PEREZ | F31: LUISA HERNANDEZ TEJADA | G31: HP0012 | H31: HANDPICO HIPERPIGMENTACIONES | I31: HANDPICO - PROCEDIMIENTOS | J31: PROCEDIMIENTOS | K31: 1034 HANDPICO | L31: 700000 | M31: 350000 | N31: 0 | O31: 0 | P31: 0 | Q31: 0 | R31: 350000 | S31: 350000 | T31: Revisar insumos | U31: SI | W31: SIN PAGO | X31: GOOGLE | Y31: 20
A32: 34655 | B32: 24814 | C32: 46080 | D32: CC 1214735381 | E32: KEVIN ESTEBAN ANGEL GARCIA | F32: LUISA HERNANDEZ TEJADA | G32: N00003 | H32: NANOPORE CICATRICES | I32: NANOPORE - PROCEDIMIENTOS | J32: PROCEDIMIENTOS | K32: N/A NANOPORE | L32: 700000 | M32: 350000 | N32: 0 | O32: 0 | P32: 0 | Q32: 0 | R32: 350000 | S32: 350000 | T32: Revisar insumos | U32: SI | W32: SIN PAGO | X32: INSTAGRAM | Y32: 29
A33: 34446 | B33: 24818 | C33: 46074 | D33: CC 1128446377 | E33: EDILSA BUITRAGO GARCIA | F33: MARIA CAMILA ZULUAGA ALVAREZ | G33: P00008 | H33: PEELING MELASMA MELINE | I33: PEELING - PROCEDIMIENTOS | J33: PROCEDIMIENTOS | L33: 900000 | M33: 450000 | N33: 0 | O33: 0 | P33: 0 | Q33: 0 | R33: 450000 | S33: 450000 | T33: Revisar insumos | U33: SI | W33: SIN PAGO | X33: INSTAGRAM | Y33: 38
A34: 34446 | B34: 24819 | C34: 46074 | D34: CC 1128446377 | E34: EDILSA BUITRAGO GARCIA | F34: MARIA CAMILA ZULUAGA ALVAREZ | G34: P00009 | H34: PEELING DESPIGMENTANTE DE OJERAS | I34: PEELING - PROCEDIMIENTOS | J34: PROCEDIMIENTOS | L34: 1900000 | M34: 950000 | N34: 0 | O34: 0 | P34: 0 | Q34: 0 | R34: 950000 | S34: 950000 | T34: Revisar insumos | U34: SI | W34: SIN PAGO | X34: INSTAGRAM | Y34: 38
A35: 35543 | B35: 24889 | C35: 46074 | D35: CC 1152202772 | E35: VANESSA DURANGO TABORDA | F35: DANIELA ASTAROT SALAZAR URIBE | G35: IP0001 | H35: IPL PROCEDIMIENTOS POR ZONA | I35: IPL-SQ - PROCEDIMIENTOS | J35: PROCEDIMIENTOS | K35: 43 IPL-SQ | L35: 100000 | M35: 65000 | N35: 0 | O35: 0 | P35: 0 | Q35: 0 | R35: 35000 | S35: 35000 | T35: Revisar insumos | U35: SI | W35: SIN PAGO | X35: AMIG@ | Y35: 32
A36: 25459 | B36: 24912 | C36: 46074 | D36: CC 1067093514 | E36: JESSICA PAOLA GUZMAN ALEMAN | F36: LUISA FERNANDA CORREA HERNANDEZ | G36: DL0002 | H36: DEPILACION ZONA MEDIANA ( ROSTRO COMPLETO, BIKINI) | I36: DEPILACION - COSMETOLOGÍA | J36: COSMETOLOGÍA | K36: 1050 DEPILACIÓN REMOVALL | L36: 90000 | M36: 15300 | N36: 0 | O36: 0 | P36: 0 | Q36: 0 | R36: 74700 | S36: 74700 | T36: Revisar insumos | U36: SI | W36: SIN PAGO | X36: GOOGLE | Y36: 35
A37: 32879 | B37: 24916 | C37: 46074 | D37: CC 1000438804 | E37: FELIPE GARZON TORRES | F37: DANIELA ASTAROT SALAZAR URIBE | G37: PD0007 | H37: CICATRICES ACNE - PRODEEP | I37: PRODEEP - PROCEDIMIENTOS | J37: PROCEDIMIENTOS | K37: 59 PRODEEP | L37: 1100000 | M37: 550000 | N37: 0 | O37: 0 | P37: 0 | Q37: 0 | R37: 550000 | S37: 550000 | T37: Revisar insumos | U37: SI | W37: SIN PAGO | X37: INSTAGRAM | Y37: 23
A38: 32879 | B38: 24917 | C38: 46074 | D38: CC 1000438804 | E38: FELIPE GARZON TORRES | F38: DANIELA ASTAROT SALAZAR URIBE | G38: 868116 | H38: SUBCISION | I38: PROCE DERMA - PROCEDIMIENTOS | J38: PROCEDIMIENTOS | K38: 59 PRODEEP | L38: 200000 | M38: 100000 | N38: 0 | O38: 0 | P38: 0 | Q38: 0 | R38: 100000 | S38: 100000 | T38: Revisar insumos | U38: SI | W38: SIN PAGO | X38: INSTAGRAM | Y38: 23
A39: 35554 | B39: 24922 | C39: 46074 | D39: CC 1020402627 | E39: YEIDY NATALY RAMIREZ BONILLA | F39: STEPHANIA LAGUADO GONZALEZ | G39: 861426 | H39: JALUPRO CLASIC | I39: INYECTABLES - PROCEDIMIENTOS | J39: PROCEDIMIENTOS | L39: 900000 | M39: 450000 | N39: 0 | O39: 0 | P39: 0 | Q39: 0 | R39: 450000 | S39: 450000 | T39: Revisar insumos | U39: SI | W39: SIN PAGO | X39: AMIG@ | Y39: 39
A40: 35579 | B40: 24954 | C40: 46081 | D40: CC 1001028073 | E40: GISELA MARTINEZ PALACIOS | F40: PAULA ANDREA ARISTIZABAL DIAZ | G40: 890303 | H40: CONSULTA DE CONTROL O DE SEGUIMIENTO POR ESPECIALISTA EN DERMATOLOGÍA < 1 MES | I40: PROCE DERMA - PROCEDIMIENTOS | J40: PROCEDIMIENTOS | L40: 0 | M40: 0 | N40: 0 | O40: 0 | P40: 0 | Q40: 0 | R40: 0 | S40: 0 | T40: 0 | U40: SI | W40: SIN PAGO | X40: FACEBOOK | Y40: 25
...

Sheet INFO.RENTABILIDAD
A1: # Atención | B1: # Registro | C1: Fecha Realización | D1: Doc. Paciente | E1: Nombre Paciente | F1: Personal Atiende | G1: Códio Cups | H1: Cups | I1: Sub Categoria | J1: Categoria | K1: Dispositivo | L1: Vlr | M1: Costo Comisiones | N1: Costo Insumos | O1: Costo Bancario | P1: Costo Adicional | Q1: Rentabilidad Insumos | R1: Rentabilidad Equipos | S1: Rentabilidad Total | T1: Promedio Porcentaje | U1: Observaciones | V1: Fecha Facturación | W1: Pagado este mes | X1: Procedencia / Recomendacion | Y1: Edad del paciente | Z1: Numero Factura
A2: 34927 | B2: 23972 | C2: 46055 | D2: CC 21690208 | E2: ROSA AMELIA LOPEZ | F2: DAVID CHALARCA CANAS | G2: 890242 | H2: CONSULTA DE PRIMERA VEZ POR MEDICINA ESPECIALIZADA -DERMATOL | I2: CONSULTA PRIMERA VEZ | J2: CONSULTA | L2: 250000 | M2: 125000 | N2: 0 | O2: 0 | P2: 0 | Q2: 0 | R2: 0 | S2: 125000 | T2: 0.5 | V2: 2026-02-02 08:56:00 | W2: SI | X2: INSTAGRAM | Y2: 76 | Z2: FE13840 | AA2: COLOMBIA | AB2: 3108243083
A3: 35869 | B3: 25474 | C3: 46055 | D3: CC 1017200704 | E3: ANA MARIA GAVIRIA LONDOÑO | F3: LUISA HERNANDEZ TEJADA | G3: 890242 | H3: CONSULTA DE PRIMERA VEZ POR MEDICINA ESPECIALIZADA -DERMATOL | I3: CONSULTA PRIMERA VEZ | J3: CONSULTA | L3: 250000 | M3: 122500 | N3: 0 | O3: 5000 | P3: 0 | Q3: 0 | R3: 0 | S3: 122500 | T3: 0.49 | V3: 2026-02-02 08:57:00 | W3: SI | X3: AMIG@ | Y3: 33 | Z3: FE13841 | AA3: COLOMBIA | AB3: 3218495568
A4: 34445 | B4: 24779 | C4: 46055 | D4: CC 1037620729 | E4: ISMAEL ARROYAVE MARTINEZ | F4: DAVID CHALARCA CANAS | G4: 860101 | H4: BIOPSIA 1 LESION | I4: PROCE DERMA | J4: PROCEDIMIENTOS | L4: 550000 | M4: 173950 | N4: 9189 | O4: 11000 | P4: 180000 | Q4: 1911 | R4: 0 | S4: 175861 | T4: 0.31974727 | V4: 2026-02-02 08:41:00 | W4: SI | X4: INSTAGRAM | Y4: 33 | Z4: FE13839 | AA4: COLOMBIA | AB4: 3107464774
A5: 35859 | B5: 25461 | C5: 46055 | D5: CC 1152435193 | E5: LAURA PATRICIA JARAMILLO PEREIRA | F5: LUISA HERNANDEZ TEJADA | G5: 890242 | H5: CONSULTA DE PRIMERA VEZ POR MEDICINA ESPECIALIZADA -DERMATOL | I5: CONSULTA PRIMERA VEZ | J5: CONSULTA | L5: 250000 | M5: 122500 | N5: 0 | O5: 5000 | P5: 0 | Q5: 0 | R5: 0 | S5: 122500 | T5: 0.49 | V5: 2026-02-02 09:20:00 | W5: SI | X5: INSTAGRAM | Y5: 35 | Z5: FE13842 | AA5: COLOMBIA | AB5: 317 5735491
A6: 35960 | B6: 25631 | C6: 46055 | D6: CC 43111978 | E6: MARIA EDINIA VILLA QUINTERO | F6: DANIELA ASTAROT SALAZAR URIBE | G6: 890242 | H6: CONSULTA DE PRIMERA VEZ POR MEDICINA ESPECIALIZADA -DERMATOL | I6: CONSULTA PRIMERA VEZ | J6: CONSULTA | L6: 250000 | M6: 125000 | N6: 0 | O6: 0 | P6: 0 | Q6: 0 | R6: 0 | S6: 125000 | T6: 0.5 | V6: 2026-02-02 09:42:00 | W6: SI | X6: INSTAGRAM | Y6: 46 | Z6: FE13843 | AA6: COLOMBIA | AB6: 3103939698
A7: 35990 | B7: 25697 | C7: 46055 | D7: CC 1020738142 | E7: CAROLINA AYALA JARAMILLO | F7: JURANY SANCHEZ | G7: 890242 | H7: CONSULTA DE PRIMERA VEZ POR MEDICINA ESPECIALIZADA -DERMATOL | I7: CONSULTA PRIMERA VEZ | J7: CONSULTA | L7: 250000 | M7: 122500 | N7: 0 | O7: 5000 | P7: 0 | Q7: 0 | R7: 0 | S7: 122500 | T7: 0.49 | V7: 2026-02-02 09:56:00 | W7: SI | X7: MEDICO | Y7: 37 | Z7: FE13844 | AA7: COLOMBIA | AB7: 3176692683
A8: 35816 | B8: 25374 | C8: 46055 | D8: CC 32354027 | E8: LINA MARIA PELAEZ | F8: LUISA HERNANDEZ TEJADA | G8: 890242 | H8: CONSULTA DE PRIMERA VEZ POR MEDICINA ESPECIALIZADA -DERMATOL | I8: CONSULTA PRIMERA VEZ | J8: CONSULTA | L8: 170000 | M8: 83300 | N8: 0 | O8: 3400 | P8: 0 | Q8: 0 | R8: 0 | S8: 83300 | T8: 0.49 | V8: 2026-02-02 10:28:00 | W8: SI | X8: AMIG@ | Y8: 45 | Z8: FE13846 | AA8: COLOMBIA | AB8: 3146065700
A9: 36052 | B9: 25819 | C9: 46055 | D9: PA A36782304 | E9: ARMONTE EVERETT BUTLER | F9: JURANY SANCHEZ | G9: 890242 | H9: CONSULTA DE PRIMERA VEZ POR MEDICINA ESPECIALIZADA -DERMATOL | I9: CONSULTA PRIMERA VEZ | J9: CONSULTA | L9: 250000 | M9: 122500 | N9: 0 | O9: 5000 | P9: 0 | Q9: 0 | R9: 0 | S9: 122500 | T9: 0.49 | V9: 2026-02-02 14:03:00 | W9: SI | X9: DOCTORALIA | Y9: 30 | Z9: FE13859 | AA9: ESTADOS UNIDOS | AB9: 12027166330
A10: 36012 | B10: 25736 | C10: 46055 | D10: CC 1152455748 | E10: JULIANA VALLEJO JIMENEZ | F10: PAULA ANDREA ARISTIZABAL DIAZ | G10: 890242 | H10: CONSULTA DE PRIMERA VEZ POR MEDICINA ESPECIALIZADA -DERMATOL | I10: CONSULTA PRIMERA VEZ | J10: CONSULTA | L10: 250000 | M10: 122500 | N10: 0 | O10: 5000 | P10: 0 | Q10: 0 | R10: 0 | S10: 122500 | T10: 0.49 | V10: 2026-02-02 13:42:00 | W10: SI | X10: GOOGLE | Y10: 30 | Z10: FE13856 | AA10: COLOMBIA | AB10: 3235223348
A11: 36028 | B11: 25776 | C11: 46055 | D11: CC 1025889338 | E11: SAMANTHA LANIADO GARCIA | F11: JURANY SANCHEZ | G11: 890302 | H11: CONSULTA DE CONTROL O DE SEGUIMIENTO POR MEDICINA ESPECIALIZADA > 1 MES | I11: CONSULTA CONTROL | J11: CONSULTA | L11: 180000 | M11: 88200 | N11: 0 | O11: 3600 | P11: 0 | Q11: 0 | R11: 0 | S11: 88200 | T11: 0.49 | V11: 2026-02-02 13:22:00 | W11: SI | X11: INSTAGRAM | Y11: 19 | Z11: FE13851 | AA11: COLOMBIA | AB11: 3217511369
A12: 36000 | B12: 25718 | C12: 46055 | D12: CC 41686251 | E12: LUZ STELLA CONTRERAS JAIMES | F12: DANIELA ASTAROT SALAZAR URIBE | G12: 890242 | H12: CONSULTA DE PRIMERA VEZ POR MEDICINA ESPECIALIZADA -DERMATOL | I12: CONSULTA PRIMERA VEZ | J12: CONSULTA | L12: 250000 | M12: 122500 | N12: 0 | O12: 5000 | P12: 0 | Q12: 0 | R12: 0 | S12: 122500 | T12: 0.49 | V12: 2026-02-02 13:33:00 | W12: SI | X12: INSTAGRAM | Y12: 67 | Z12: FE13854 | AA12: COLOMBIA | AB12: 4042188771
A13: 36001 | B13: 25721 | C13: 46055 | D13: PA X7881648 | E13: SHAYAN KHAJEHNOURI | F13: JURANY SANCHEZ | G13: 890242 | H13: CONSULTA DE PRIMERA VEZ POR MEDICINA ESPECIALIZADA -DERMATOL | I13: CONSULTA PRIMERA VEZ | J13: CONSULTA | L13: 250000 | M13: 122500 | N13: 0 | O13: 5000 | P13: 0 | Q13: 0 | R13: 0 | S13: 122500 | T13: 0.49 | V13: 2026-02-02 14:08:00 | W13: SI | X13: DOCTORALIA | Y13: 25 | Z13: FE13860 | AA13: SUIZA | AB13: 41791540512
A14: 34589 | B14: 23461 | C14: 46055 | D14: CC 1128444869 | E14: ADRIAN ANDRES RAMIREZ | F14: PAULA ANDREA ARISTIZABAL DIAZ | G14: 890302 | H14: CONSULTA DE CONTROL O DE SEGUIMIENTO POR MEDICINA ESPECIALIZADA > 1 MES | I14: CONSULTA CONTROL | J14: CONSULTA | L14: 180000 | M14: 90000 | N14: 0 | O14: 0 | P14: 0 | Q14: 0 | R14: 0 | S14: 90000 | T14: 0.5 | V14: 2026-02-02 11:28:00 | W14: SI | X14: AMIG@ | Y14: 38 | Z14: FE13847 | AA14: COLOMBIA | AB14: 3117783365
A15: 35512 | B15: 24840 | C15: 46055 | D15: PPT 6859027 | E15: YEMMIRET BEATRIZ CORTEZ GONZALEZ | F15: PAULA ANDREA ARISTIZABAL DIAZ | G15: 890303 | H15: CONSULTA DE CONTROL - PROCEDIMIENTO | I15: CONSULTA CONTROL | J15: CONSULTA | L15: 0 | M15: 0 | N15: 0 | O15: 0 | P15: 0 | Q15: 0 | R15: 0 | S15: 0 | T15: 0 | W15: SIN PAGO | X15: INSTAGRAM | Y15: 22 | AA15: VENEZUELA | AB15: 3043238624
A16: 35966 | B16: 25645 | C16: 46055 | D16: CC 1003308616 | E16: JIMENA FUENTES | F16: LUISA HERNANDEZ TEJADA | G16: 890242 | H16: CONSULTA DE PRIMERA VEZ POR MEDICINA ESPECIALIZADA -DERMATOL | I16: CONSULTA PRIMERA VEZ | J16: CONSULTA | L16: 250000 | M16: 122500 | N16: 0 | O16: 5000 | P16: 0 | Q16: 0 | R16: 0 | S16: 122500 | T16: 0.49 | V16: 2026-02-02 13:27:00 | W16: SI | X16: GOOGLE | Y16: 24 | Z16: FE13853 | AA16: COLOMBIA | AB16: 3212808037
A17: 36051 | B17: 25818 | C17: 46055 | D17: CC 1020738142 | E17: CAROLINA AYALA JARAMILLO | F17: JURANY SANCHEZ | G17: LP0003 | H17: TELANGIECTASIAS FACIALES 6-10 - LONGPULSE | I17: LONGPULSE | J17: PROCEDIMIENTOS | K17: LONGPULSE | L17: 800000 | M17: 392000 | N17: 0 | O17: 16000 | P17: 0 | Q17: 0 | R17: 0 | S17: 392000 | T17: 0.49 | V17: 2026-02-02 13:00:00 | W17: SI | X17: MEDICO | Y17: 37 | Z17: FE13848 | AA17: COLOMBIA | AB17: 3176692683
A18: 35497 | B18: 25172 | C18: 46055 | D18: PA A00817909 | E18: LUIS GABRIEL RIVERA MENDOZA | F18: PAULA ANDREA ARISTIZABAL DIAZ | G18: 868116 | H18: SUBCISION | I18: PROCE DERMA | J18: PROCEDIMIENTOS | L18: 200000 | M18: 89615 | N18: 14583 | O18: 4000 | P18: 0 | Q18: 2187 | R18: 0 | S18: 91802 | T18: 0.45901 | V18: 2026-01-21 13:45:00 | W18: NO | X18: INSTAGRAM | Y18: 44 | Z18: FE13574 | AA18: PUERTO RICO | AB18: 17879105036
A19: 35996 | B19: 25713 | C19: 46055 | D19: CC 38234538 | E19: BEATRIZ EUGENIA VALLEJO CADAVID | F19: DAVID CHALARCA CANAS | G19: 890242 | H19: CONSULTA DE PRIMERA VEZ POR MEDICINA ESPECIALIZADA -DERMATOL | I19: CONSULTA PRIMERA VEZ | J19: CONSULTA | L19: 250000 | M19: 122500 | N19: 0 | O19: 5000 | P19: 0 | Q19: 0 | R19: 0 | S19: 122500 | T19: 0.49 | V19: 2026-02-02 14:12:00 | W19: SI | X19: PAGINA WEB | Y19: 71 | Z19: FE13862 | AA19: COLOMBIA | AB19: 3053325374
A20: 35993 | B20: 25701 | C20: 46055 | D20: TI 1026002032 | E20: STIVEN RAMIREZ MARTINEZ | F20: DAVID CHALARCA CANAS | G20: 890302 | H20: CONSULTA DE CONTROL O DE SEGUIMIENTO POR MEDICINA ESPECIALIZADA > 1 MES | I20: CONSULTA CONTROL | J20: CONSULTA | L20: 180000 | M20: 88200 | N20: 0 | O20: 3600 | P20: 0 | Q20: 0 | R20: 0 | S20: 88200 | T20: 0.49 | V20: 2026-02-02 14:11:00 | W20: SI | X20: MEDICO | Y20: 15 | Z20: FE13861 | AA20: COLOMBIA | AB20: 3107482914
A21: 36058 | B21: 25830 | C21: 46055 | D21: CC 41686251 | E21: LUZ STELLA CONTRERAS JAIMES | F21: DANIELA ASTAROT SALAZAR URIBE | G21: LC0008 | H21: CO2 FULGURACION 1- 5 LESIONES MENORES 0.5 CM | I21: LASER IBLAZE (CO2) | J21: PROCEDIMIENTOS | K21: LÁSER IBLAZE (CO2) | L21: 450000 | M21: 220500 | N21: 0 | O21: 9000 | P21: 0 | Q21: 0 | R21: 0 | S21: 220500 | T21: 0.49 | V21: 2026-02-02 13:36:00 | W21: SI | X21: INSTAGRAM | Y21: 67 | Z21: FE13855 | AA21: COLOMBIA | AB21: 4042188771
A22: 35634 | B22: 25846 | C22: 46055 | D22: PA 7615390 | E22: DARIO FARINELLI | F22: DANIELA ASTAROT SALAZAR URIBE | G22: LC0008 | H22: CO2 FULGURACION 1- 5 LESIONES MENORES 0.5 CM | I22: LASER IBLAZE (CO2) | J22: PROCEDIMIENTOS | K22: LÁSER IBLAZE (CO2) | L22: 0 | M22: 0 | N22: 0 | O22: 0 | P22: 0 | Q22: 0 | R22: 0 | S22: 0 | T22: 0 | W22: SIN PAGO | X22: INSTAGRAM | Y22: 42 | AA22: AUSTRALIA | AB22: 61434263261
A23: 35959 | B23: 25821 | C23: 46055 | D23: CC 1036397369 | E23: ESTEFANIA GARCIA OSORIO | F23: DANIELA ASTAROT SALAZAR URIBE | G23: 861401 | H23: INFILTRACION INTRALESIONAL 1-5 LESIONES | I23: PROCE DERMA | J23: PROCEDIMIENTOS | L23: 300000 | M23: 147000 | N23: 0 | O23: 6000 | P23: 0 | Q23: 0 | R23: 0 | S23: 147000 | T23: 0.49 | V23: 2026-02-02 13:15:00 | W23: SI | X23: GOOGLE | Y23: 33 | Z23: FE13849 | AA23: COLOMBIA | AB23: 3007685166
A24: 35959 | B24: 25630 | C24: 46055 | D24: CC 1036397369 | E24: ESTEFANIA GARCIA OSORIO | F24: DANIELA ASTAROT SALAZAR URIBE | G24: PD0009 | H24: CICATRICES POST QUIRURGICAS 6-10 CMS - PRODEEP | I24: PRODEEP | J24: PROCEDIMIENTOS | K24: PRODEEP | L24: 600000 | M24: 294000 | N24: 0 | O24: 12000 | P24: 0 | Q24: 0 | R24: 0 | S24: 294000 | T24: 0.49 | V24: 2026-02-02 13:15:00 | W24: SI | X24: GOOGLE | Y24: 33 | Z24: FE13850 | AA24: COLOMBIA | AB24: 3007685166
A25: 36058 | B25: 25829 | C25: 46055 | D25: CC 41686251 | E25: LUZ STELLA CONTRERAS JAIMES | F25: DANIELA ASTAROT SALAZAR URIBE | G25: LP0009 | H25: LAGO VENOSO - LONGPULSE | I25: LONGPULSE | J25: PROCEDIMIENTOS | K25: LONGPULSE | L25: 1000000 | M25: 490000 | N25: 0 | O25: 20000 | P25: 0 | Q25: 0 | R25: 0 | S25: 490000 | T25: 0.49 | V25: 2026-02-02 13:36:00 | W25: SI | X25: INSTAGRAM | Y25: 67 | Z25: FE13855 | AA25: COLOMBIA | AB25: 4042188771
A26: 36058 | B26: 25828 | C26: 46055 | D26: CC 41686251 | E26: LUZ STELLA CONTRERAS JAIMES | F26: DANIELA ASTAROT SALAZAR URIBE | G26: P00008 | H26: PEELING MELASMA MELINE | I26: PEELING | J26: PROCEDIMIENTOS | L26: 1000000 | M26: 403300 | N26: 133120.58 | O26: 20000 | P26: 0 | Q26: 40279.42 | R26: 0 | S26: 443579.42 | T26: 0.44357942 | V26: 2026-02-02 13:36:00 | W26: SI | X26: INSTAGRAM | Y26: 67 | Z26: FE13855 | AA26: COLOMBIA | AB26: 4042188771
A27: 36058 | B27: 25835 | C27: 46055 | D27: CC 41686251 | E27: LUZ STELLA CONTRERAS JAIMES | F27: DANIELA ASTAROT SALAZAR URIBE | G27: P00008 | H27: PEELING MELASMA MELINE | I27: PEELING | J27: PROCEDIMIENTOS | L27: 1800000 | M27: 501183 | N27: 633069.55 | O27: 36000 | P27: 0 | Q27: 128564.45 | R27: 0 | S27: 629747.45 | T27: 0.34985969 | V27: 2026-02-02 13:36:00 | W27: SI | X27: INSTAGRAM | Y27: 67 | Z27: FE13855 | AA27: COLOMBIA | AB27: 4042188771
A28: 35497 | B28: 25407 | C28: 46055 | D28: PA A00817909 | E28: LUIS GABRIEL RIVERA MENDOZA | F28: PAULA ANDREA ARISTIZABAL DIAZ | G28: LC0001 | H28: CO2 CICATRICES ACNE CARA | I28: LASER Co2 | J28: PROCEDIMIENTOS | K28: LÁSER IBLAZE (CO2) | L28: 1000000 | M28: 490000 | N28: 0 | O28: 20000 | P28: 0 | Q28: 0 | R28: 0 | S28: 490000 | T28: 0.49 | V28: 2026-02-02 14:01:00 | W28: SI | X28: INSTAGRAM | Y28: 44 | Z28: FE13858 | AA28: PUERTO RICO | AB28: 17879105036
A29: 35497 | B29: 25831 | C29: 46055 | D29: PA A00817909 | E29: LUIS GABRIEL RIVERA MENDOZA | F29: PAULA ANDREA ARISTIZABAL DIAZ | G29: M00011 | H29: FOTOAGE | I29: FOTOAGE | J29: PROCEDIMIENTOS | K29: DISPOSITIVO FOTOAGE | L29: 0 | M29: 0 | N29: 0 | O29: 0 | P29: 0 | Q29: 0 | R29: 0 | S29: 0 | T29: 0 | W29: SIN PAGO | X29: INSTAGRAM | Y29: 44 | AA29: PUERTO RICO | AB29: 17879105036
A30: 35939 | B30: 25595 | C30: 46055 | D30: CC 1090488619 | E30: KAREN ANDREA PEREZ SARAVIA | F30: DAVID CHALARCA CANAS | G30: 890242 | H30: CONSULTA DE PRIMERA VEZ POR MEDICINA ESPECIALIZADA -DERMATOL | I30: CONSULTA PRIMERA VEZ | J30: CONSULTA | L30: 250000 | M30: 122500 | N30: 0 | O30: 5000 | P30: 0 | Q30: 0 | R30: 0 | S30: 122500 | T30: 0.49 | V30: 2026-02-02 14:35:00 | W30: SI | X30: INSTAGRAM | Y30: 30 | Z30: FE13865 | AA30: COLOMBIA | AB30: 3023521130
A31: 35854 | B31: 25854 | C31: 46055 | D31: CC 1000644075 | E31: LUISA FERNANDA CORREA HERNANDEZ | F31: JURANY SANCHEZ | G31: LP0002 | H31: TELANGIECTASIAS FACIALES 1-5 - LONGPULSE | I31: LONGPULSE | J31: PROCEDIMIENTOS | K31: LONGPULSE | L31: 0 | M31: 0 | N31: 0 | O31: 0 | P31: 0 | Q31: 0 | R31: 0 | S31: 0 | T31: 0 | W31: SIN PAGO | X31: MEDICO | Y31: 24 | AA31: COLOMBIA | AB31: 3162859884
A32: 36053 | B32: 25820 | C32: 46055 | D32: CC 79054647 | E32: MAURICIO TORRES RINCON | F32: DAVID CHALARCA CANAS | G32: 863101 | H32: CRIOTERAPIA 1-5 LESIONES | I32: PROCE DERMA | J32: PROCEDIMIENTOS | L32: 350000 | M32: 172000 | N32: 0 | O32: 6000 | P32: 0 | Q32: 0 | R32: 0 | S32: 172000 | T32: 0.49142857 | V32: 2026-02-02 15:51:00 | W32: SI | X32: GOOGLE | Y32: 56 | Z32: FE13867 | AA32: COLOMBIA | AB32: 3154920199
A33: 36075 | B33: 25859 | C33: 46055 | D33: CC 43021146 | E33: MARIA EDITH GOMEZ PALACIO | F33: DAVID CHALARCA CANAS | G33: 890242 | H33: CONSULTA DE PRIMERA VEZ POR MEDICINA ESPECIALIZADA -DERMATOL | I33: CONSULTA PRIMERA VEZ | J33: CONSULTA | L33: 200000 | M33: 98000 | N33: 0 | O33: 4000 | P33: 0 | Q33: 0 | R33: 0 | S33: 98000 | T33: 0.49 | V33: 2026-02-02 17:59:00 | W33: SI | X33: VITRINA | Y33: 71 | Z33: FE13874 | AA33: COLOMBIA | AB33: 3218306660
A34: 35947 | B34: 25609 | C34: 46055 | D34: CC 1036943258 | E34: CRISTIAN CAMILO BARRERA ARIAS | F34: JURANY SANCHEZ | G34: 890242 | H34: CONSULTA DE PRIMERA VEZ POR MEDICINA ESPECIALIZADA -DERMATOL | I34: CONSULTA PRIMERA VEZ | J34: CONSULTA | L34: 250000 | M34: 122500 | N34: 0 | O34: 5000 | P34: 0 | Q34: 0 | R34: 0 | S34: 122500 | T34: 0.49 | V34: 2026-02-02 17:03:00 | W34: SI | X34: GOOGLE | Y34: 33 | Z34: FE13870 | AA34: COLOMBIA | AB34: 3146570663
A35: 35708 | B35: 25646 | C35: 46055 | D35: CC 1037973105 | E35: JOHANA ANDREA QUENGUAN MARIN | F35: DANIELA ASTAROT SALAZAR URIBE | G35: 861416 | H35: APLICACIÓN BIOESTIMULADOR HARMONYCA | I35: INYECTABLES | J35: PROCEDIMIENTOS | L35: 4000000 | M35: 889840 | N35: 1615793 | O35: 80000 | P35: 0 | Q35: 524527 | R35: 0 | S35: 1414367 | T35: 0.35359175 | V35: 2026-02-02 14:46:00 | W35: SI | X35: GOOGLE | Y35: 37 | Z35: FE13866 | AA35: COLOMBIA | AB35: 3117114819
A36: 35708 | B36: 25647 | C36: 46055 | D36: CC 1037973105 | E36: JOHANA ANDREA QUENGUAN MARIN | F36: DANIELA ASTAROT SALAZAR URIBE | G36: 861411 | H36: APLICACIÓN TOXINA BOTULINICA | I36: INYECTABLES | J36: PROCEDIMIENTOS | L36: 0 | M36: 0 | N36: 0 | O36: 0 | P36: 0 | Q36: 0 | R36: 0 | S36: 0 | T36: 0 | W36: SIN PAGO | X36: GOOGLE | Y36: 37 | AA36: COLOMBIA | AB36: 3117114819
A37: 35120 | B37: 24223 | C37: 46055 | D37: CC 1007239177 | E37: SARA OQUENDO TORRES | F37: DAVID CHALARCA CANAS | G37: 890303 | H37: CONSULTA DE CONTROL O DE SEGUIMIENTO POR ESPECIALISTA EN DERMATOLOGÍA < 1 MES | I37: PROCE DERMA | J37: PROCEDIMIENTOS | L37: 0 | M37: 0 | N37: 0 | O37: 0 | P37: 0 | Q37: 0 | R37: 0 | S37: 0 | T37: 0 | W37: SIN PAGO | X37: INSTAGRAM | Y37: 25 | AA37: COLOMBIA | AB37: 3503348467
A38: 28241 | B38: 25869 | C38: 46055 | D38: CC 1035854913 | E38: JURANY SANCHEZ | F38: ISABELLA GONZALEZ MEJIA | G38: TM0002 | H38: TENSAMAX ZONA MEDIANA | I38: TENSAMAX | J38: COSMETOLOGÍA | K38: TENSAMAX | L38: 0 | M38: 0 | N38: 0 | O38: 0 | P38: 0 | Q38: 0 | R38: 0 | S38: 0 | T38: 0 | W38: SIN PAGO | X38: MEDICO | Y38: 36 | AA38: COLOMBIA | AB38: 3008249135
A39: 36031 | B39: 25781 | C39: 46055 | D39: TI 1035001139 | E39: VALERIA DELGADO COUTIN | F39: JURANY SANCHEZ | G39: 890242 | H39: CONSULTA DE PRIMERA VEZ POR MEDICINA ESPECIALIZADA -DERMATOL | I39: CONSULTA PRIMERA VEZ | J39: CONSULTA | L39: 250000 | M39: 125000 | N39: 0 | O39: 0 | P39: 0 | Q39: 0 | R39: 0 | S39: 125000 | T39: 0.5 | V39: 2026-02-02 16:56:00 | W39: SI | X39: INSTAGRAM | Y39: 13 | Z39: FE13868 | AA39: COLOMBIA | AB39: 3113894613
A40: 34985 | B40: 24219 | C40: 46055 | D40: CC 1001818423 | E40: YULISA MICHEL MARRIAGA DURAN | F40: LUISA HERNANDEZ TEJADA | G40: IP0001 | H40: IPL PROCEDIMIENTOS POR ZONA | I40: IPL-SQ | J40: PROCEDIMIENTOS | K40: IPL-SQ | L40: 650000 | M40: 318500 | N40: 0 | O40: 13000 | P40: 0 | Q40: 0 | R40: 0 | S40: 318500 | T40: 0.49 | V40: 2026-02-02 17:08:00 | W40: SI | X40: AMIG@ | Y40: 27 | Z40: FE13871 | AA40: COLOMBIA | AB40: 3122689563
...

Sheet TABLERO Y AGENDA
L1: META OBJETIVO | M1: PROYEC DÍA | N1: FECHA | O1: FACTURADO | P1: DÍA HABIL
B2: JUAN PABLO | C2: JUAN PABLO | D2: JUAN PABLO | L2: MABEL | M2: MABEL | N2: MABEL | O2: MABEL | P2: MABEL
B3: FECHA | C3: PROYECIÓN INICIO MES | D3: PROYECIÓN QUINCENA | E3: GESTIÓN COMERCIAL REAL | F3: PAGO SI | G3: PAGO NO | H3: SIN PAGO | I3: SERVICIOS PRESTADOS | J3: % DIF | L3: 19347826 | M3: 3190000 | N3: 46072 | O3: 24284000 | P3: 16
B4: 46054 | C4: 0 | D4: 0 | E4: =SUMIF(INFO.PROYECCIÓN!$C:$C,B4,INFO.PROYECCIÓN!$L:$L) -> 0 | F4: =SUMIFS(INFO.RENTABILIDAD!$L$1:$L$15000,INFO.RENTABILIDAD!$C$1:$C$15000,B4,INFO.RENTABILIDAD!$W$1:$W$15000,"SI") -> 133000 | G4: =SUMIFS(INFO.RENTABILIDAD!$L$1:$L$999,INFO.RENTABILIDAD!$C$1:$C$999,B4,INFO.RENTABILIDAD!$W$1:$W$999,"NO") -> 0 | H4: =SUMIFS(INFO.RENTABILIDAD!$L$1:$L$999,INFO.RENTABILIDAD!$C$1:$C$999,B4,INFO.RENTABILIDAD!$W$1:$W$999,"SIN PAGO") -> 0 | I4: =SUMIF(INFO.RENTABILIDAD!C:C,B4,INFO.RENTABILIDAD!L:L) -> 133000 | J4: - | L4: TUPI GESTIÓN COMERCIAL ABRIL
B5: 46055 | C5: 0 | D5: 0 | E5: =SUMIF(INFO.PROYECCIÓN!$C:$C,B5,INFO.PROYECCIÓN!$L:$L) -> 0 | F5: =SUMIFS(INFO.RENTABILIDAD!$L$1:$L$15000,INFO.RENTABILIDAD!$C$1:$C$15000,B5,INFO.RENTABILIDAD!$W$1:$W$15000,"SI") -> 23167000 | G5: =SUMIFS(INFO.RENTABILIDAD!$L$1:$L$999,INFO.RENTABILIDAD!$C$1:$C$999,B5,INFO.RENTABILIDAD!$W$1:$W$999,"NO") -> 200000 | H5: =SUMIFS(INFO.RENTABILIDAD!$L$1:$L$999,INFO.RENTABILIDAD!$C$1:$C$999,B5,INFO.RENTABILIDAD!$W$1:$W$999,"SIN PAGO") -> 0 | I5: =SUMIF(INFO.RENTABILIDAD!C:C,B5,INFO.RENTABILIDAD!L:L) -> 23367000 | J5: - | L5: FECHAS | M5: RESULTADO | N5: PROYECCIÓN ABRIL | O5: GESTIÓN COM | P5: S. PRESTADOS
B6: 46056 | C6: 0 | D6: 0 | E6: =SUMIF(INFO.PROYECCIÓN!$C:$C,B6,INFO.PROYECCIÓN!$L:$L) -> 0 | F6: =SUMIFS(INFO.RENTABILIDAD!$L$1:$L$15000,INFO.RENTABILIDAD!$C$1:$C$15000,B6,INFO.RENTABILIDAD!$W$1:$W$15000,"SI") -> 14266000 | G6: =SUMIFS(INFO.RENTABILIDAD!$L$1:$L$999,INFO.RENTABILIDAD!$C$1:$C$999,B6,INFO.RENTABILIDAD!$W$1:$W$999,"NO") -> 1350000 | H6: =SUMIFS(INFO.RENTABILIDAD!$L$1:$L$999,INFO.RENTABILIDAD!$C$1:$C$999,B6,INFO.RENTABILIDAD!$W$1:$W$999,"SIN PAGO") -> 0 | I6: =SUMIF(INFO.RENTABILIDAD!C:C,B6,INFO.RENTABILIDAD!L:L) -> 15616000 | J6: - | M6: SEMANA 1 | N6: =SUM(C4:C8) -> 0 | O6: =SUM(E4:E8) -> 0 | P6: =SUM(I4:I8) -> 61422500
B7: 46057 | C7: 0 | D7: 0 | E7: =SUMIF(INFO.PROYECCIÓN!$C:$C,B7,INFO.PROYECCIÓN!$L:$L) -> 0 | F7: =SUMIFS(INFO.RENTABILIDAD!$L$1:$L$15000,INFO.RENTABILIDAD!$C$1:$C$15000,B7,INFO.RENTABILIDAD!$W$1:$W$15000,"SI") -> 6521000 | G7: =SUMIFS(INFO.RENTABILIDAD!$L$1:$L$999,INFO.RENTABILIDAD!$C$1:$C$999,B7,INFO.RENTABILIDAD!$W$1:$W$999,"NO") -> 381000 | H7: =SUMIFS(INFO.RENTABILIDAD!$L$1:$L$999,INFO.RENTABILIDAD!$C$1:$C$999,B7,INFO.RENTABILIDAD!$W$1:$W$999,"SIN PAGO") -> 0 | I7: =SUMIF(INFO.RENTABILIDAD!C:C,B7,INFO.RENTABILIDAD!L:L) -> 6902000 | J7: - | M7: SEMANA 2 | N7: =SUM(C9:C15) -> 0 | O7: =SUM(E9:E15) -> 0 | P7: =SUM(I9:I15) -> 114190500
B8: 46058 | C8: 0 | D8: 0 | E8: =SUMIF(INFO.PROYECCIÓN!$C:$C,B8,INFO.PROYECCIÓN!$L:$L) -> 0 | F8: =SUMIFS(INFO.RENTABILIDAD!$L$1:$L$15000,INFO.RENTABILIDAD!$C$1:$C$15000,B8,INFO.RENTABILIDAD!$W$1:$W$15000,"SI") -> 13902000 | G8: =SUMIFS(INFO.RENTABILIDAD!$L$1:$L$999,INFO.RENTABILIDAD!$C$1:$C$999,B8,INFO.RENTABILIDAD!$W$1:$W$999,"NO") -> 1502500 | H8: =SUMIFS(INFO.RENTABILIDAD!$L$1:$L$999,INFO.RENTABILIDAD!$C$1:$C$999,B8,INFO.RENTABILIDAD!$W$1:$W$999,"SIN PAGO") -> 0 | I8: =SUMIF(INFO.RENTABILIDAD!C:C,B8,INFO.RENTABILIDAD!L:L) -> 15404500 | J8: - | M8: SEMANA 3 | N8: =SUM(C16:C22) -> 0 | O8: =SUM(E16:E22) -> 0 | P8: =SUM(I16:I22) -> 137771000
B9: 46059 | C9: 0 | D9: 0 | E9: =SUMIF(INFO.PROYECCIÓN!$C:$C,B9,INFO.PROYECCIÓN!$L:$L) -> 0 | F9: =SUMIFS(INFO.RENTABILIDAD!$L$1:$L$15000,INFO.RENTABILIDAD!$C$1:$C$15000,B9,INFO.RENTABILIDAD!$W$1:$W$15000,"SI") -> 24645000 | G9: =SUMIFS(INFO.RENTABILIDAD!$L$1:$L$999,INFO.RENTABILIDAD!$C$1:$C$999,B9,INFO.RENTABILIDAD!$W$1:$W$999,"NO") -> 123500 | H9: =SUMIFS(INFO.RENTABILIDAD!$L$1:$L$999,INFO.RENTABILIDAD!$C$1:$C$999,B9,INFO.RENTABILIDAD!$W$1:$W$999,"SIN PAGO") -> 0 | I9: =SUMIF(INFO.RENTABILIDAD!C:C,B9,INFO.RENTABILIDAD!L:L) -> 24768500 | J9: - | M9: SEMANA 4 | N9: =SUM(C23:C29) -> 0 | O9: =SUM(E23:E29) -> 85912500 | P9: =SUM(I23:I29) -> 0
B10: 46060 | C10: 0 | D10: 0 | E10: =SUMIF(INFO.PROYECCIÓN!$C:$C,B10,INFO.PROYECCIÓN!$L:$L) -> 0 | F10: =SUMIFS(INFO.RENTABILIDAD!$L$1:$L$15000,INFO.RENTABILIDAD!$C$1:$C$15000,B10,INFO.RENTABILIDAD!$W$1:$W$15000,"SI") -> 11220000 | G10: =SUMIFS(INFO.RENTABILIDAD!$L$1:$L$999,INFO.RENTABILIDAD!$C$1:$C$999,B10,INFO.RENTABILIDAD!$W$1:$W$999,"NO") -> 940000 | H10: =SUMIFS(INFO.RENTABILIDAD!$L$1:$L$999,INFO.RENTABILIDAD!$C$1:$C$999,B10,INFO.RENTABILIDAD!$W$1:$W$999,"SIN PAGO") -> 0 | I10: =SUMIF(INFO.RENTABILIDAD!C:C,B10,INFO.RENTABILIDAD!L:L) -> 12160000 | J10: - | M10: SEMANA 5 | N10: =SUM(C30:C34) -> 0 | O10: =SUM(E30:E34) -> 19120000 | P10: =SUM(I30:I34) -> 0
B11: 46061 | C11: 0 | D11: 0 | E11: =SUMIF(INFO.PROYECCIÓN!$C:$C,B11,INFO.PROYECCIÓN!$L:$L) -> 0 | F11: =SUMIFS(INFO.RENTABILIDAD!$L$1:$L$15000,INFO.RENTABILIDAD!$C$1:$C$15000,B11,INFO.RENTABILIDAD!$W$1:$W$15000,"SI") -> 610000 | G11: =SUMIFS(INFO.RENTABILIDAD!$L$1:$L$999,INFO.RENTABILIDAD!$C$1:$C$999,B11,INFO.RENTABILIDAD!$W$1:$W$999,"NO") -> 0 | H11: =SUMIFS(INFO.RENTABILIDAD!$L$1:$L$999,INFO.RENTABILIDAD!$C$1:$C$999,B11,INFO.RENTABILIDAD!$W$1:$W$999,"SIN PAGO") -> 0 | I11: =SUMIF(INFO.RENTABILIDAD!C:C,B11,INFO.RENTABILIDAD!L:L) -> 610000 | J11: - | L11: ABRIL | N11: =SUM(N6:N10) -> 0 | O11: =SUM(O6:O10) -> 105032500 | P11: =SUM(P6:P9) -> 313384000
B12: 46062 | C12: 0 | D12: 0 | E12: =SUMIF(INFO.PROYECCIÓN!$C:$C,B12,INFO.PROYECCIÓN!$L:$L) -> 0 | F12: =SUMIFS(INFO.RENTABILIDAD!$L$1:$L$15000,INFO.RENTABILIDAD!$C$1:$C$15000,B12,INFO.RENTABILIDAD!$W$1:$W$15000,"SI") -> 18849500 | G12: =SUMIFS(INFO.RENTABILIDAD!$L$1:$L$999,INFO.RENTABILIDAD!$C$1:$C$999,B12,INFO.RENTABILIDAD!$W$1:$W$999,"NO") -> 0 | H12: =SUMIFS(INFO.RENTABILIDAD!$L$1:$L$999,INFO.RENTABILIDAD!$C$1:$C$999,B12,INFO.RENTABILIDAD!$W$1:$W$999,"SIN PAGO") -> 0 | I12: =SUMIF(INFO.RENTABILIDAD!C:C,B12,INFO.RENTABILIDAD!L:L) -> 18849500 | J12: -
B13: 46063 | C13: 0 | D13: 0 | E13: =SUMIF(INFO.PROYECCIÓN!$C:$C,B13,INFO.PROYECCIÓN!$L:$L) -> 0 | F13: =SUMIFS(INFO.RENTABILIDAD!$L$1:$L$15000,INFO.RENTABILIDAD!$C$1:$C$15000,B13,INFO.RENTABILIDAD!$W$1:$W$15000,"SI") -> 26790000 | G13: =SUMIFS(INFO.RENTABILIDAD!$L$1:$L$999,INFO.RENTABILIDAD!$C$1:$C$999,B13,INFO.RENTABILIDAD!$W$1:$W$999,"NO") -> 332500 | H13: =SUMIFS(INFO.RENTABILIDAD!$L$1:$L$999,INFO.RENTABILIDAD!$C$1:$C$999,B13,INFO.RENTABILIDAD!$W$1:$W$999,"SIN PAGO") -> 0 | I13: =SUMIF(INFO.RENTABILIDAD!C:C,B13,INFO.RENTABILIDAD!L:L) -> 27122500 | J13: - | L13: ='BALANCE PPTO'!D4 -> REPORTE GENERAL
B14: 46064 | C14: 0 | D14: 0 | E14: =SUMIF(INFO.PROYECCIÓN!$C:$C,B14,INFO.PROYECCIÓN!$L:$L) -> 0 | F14: =SUMIFS(INFO.RENTABILIDAD!$L$1:$L$15000,INFO.RENTABILIDAD!$C$1:$C$15000,B14,INFO.RENTABILIDAD!$W$1:$W$15000,"SI") -> 14830000 | G14: =SUMIFS(INFO.RENTABILIDAD!$L$1:$L$999,INFO.RENTABILIDAD!$C$1:$C$999,B14,INFO.RENTABILIDAD!$W$1:$W$999,"NO") -> 0 | H14: =SUMIFS(INFO.RENTABILIDAD!$L$1:$L$999,INFO.RENTABILIDAD!$C$1:$C$999,B14,INFO.RENTABILIDAD!$W$1:$W$999,"SIN PAGO") -> 0 | I14: =SUMIF(INFO.RENTABILIDAD!C:C,B14,INFO.RENTABILIDAD!L:L) -> 14830000 | J14: - | L14: ='BALANCE PPTO'!D5 -> 46072
B15: 46065 | C15: 0 | D15: 0 | E15: =SUMIF(INFO.PROYECCIÓN!$C:$C,B15,INFO.PROYECCIÓN!$L:$L) -> 0 | F15: =SUMIFS(INFO.RENTABILIDAD!$L$1:$L$15000,INFO.RENTABILIDAD!$C$1:$C$15000,B15,INFO.RENTABILIDAD!$W$1:$W$15000,"SI") -> 15850000 | G15: =SUMIFS(INFO.RENTABILIDAD!$L$1:$L$999,INFO.RENTABILIDAD!$C$1:$C$999,B15,INFO.RENTABILIDAD!$W$1:$W$999,"NO") -> 0 | H15: =SUMIFS(INFO.RENTABILIDAD!$L$1:$L$999,INFO.RENTABILIDAD!$C$1:$C$999,B15,INFO.RENTABILIDAD!$W$1:$W$999,"SIN PAGO") -> 0 | I15: =SUMIF(INFO.RENTABILIDAD!C:C,B15,INFO.RENTABILIDAD!L:L) -> 15850000 | J15: -
B16: 46066 | C16: 0 | D16: 0 | E16: =SUMIF(INFO.PROYECCIÓN!$C:$C,B16,INFO.PROYECCIÓN!$L:$L) -> 0 | F16: =SUMIFS(INFO.RENTABILIDAD!$L$1:$L$15000,INFO.RENTABILIDAD!$C$1:$C$15000,B16,INFO.RENTABILIDAD!$W$1:$W$15000,"SI") -> 24510000 | G16: =SUMIFS(INFO.RENTABILIDAD!$L$1:$L$999,INFO.RENTABILIDAD!$C$1:$C$999,B16,INFO.RENTABILIDAD!$W$1:$W$999,"NO") -> 0 | H16: =SUMIFS(INFO.RENTABILIDAD!$L$1:$L$999,INFO.RENTABILIDAD!$C$1:$C$999,B16,INFO.RENTABILIDAD!$W$1:$W$999,"SIN PAGO") -> 0 | I16: =SUMIF(INFO.RENTABILIDAD!C:C,B16,INFO.RENTABILIDAD!L:L) -> 24510000 | J16: - | L16: ='BALANCE PPTO'!D8 -> % ESPERADO AL DÍA | M16: ='BALANCE PPTO'!E8 -> % REAL AL DÍA
B17: 46067 | C17: 0 | D17: 0 | E17: =SUMIF(INFO.PROYECCIÓN!$C:$C,B17,INFO.PROYECCIÓN!$L:$L) -> 0 | F17: =SUMIFS(INFO.RENTABILIDAD!$L$1:$L$15000,INFO.RENTABILIDAD!$C$1:$C$15000,B17,INFO.RENTABILIDAD!$W$1:$W$15000,"SI") -> 14265000 | G17: =SUMIFS(INFO.RENTABILIDAD!$L$1:$L$999,INFO.RENTABILIDAD!$C$1:$C$999,B17,INFO.RENTABILIDAD!$W$1:$W$999,"NO") -> 1240000 | H17: =SUMIFS(INFO.RENTABILIDAD!$L$1:$L$999,INFO.RENTABILIDAD!$C$1:$C$999,B17,INFO.RENTABILIDAD!$W$1:$W$999,"SIN PAGO") -> 0 | I17: =SUMIF(INFO.RENTABILIDAD!C:C,B17,INFO.RENTABILIDAD!L:L) -> 15505000 | J17: - | L17: ='BALANCE PPTO'!D9 -> 0.66666667 | M17: ='BALANCE PPTO'!E9 -> 0.58980192
B18: 46068 | C18: 0 | D18: 0 | E18: =SUMIF(INFO.PROYECCIÓN!$C:$C,B18,INFO.PROYECCIÓN!$L:$L) -> 0 | F18: =SUMIFS(INFO.RENTABILIDAD!$L$1:$L$15000,INFO.RENTABILIDAD!$C$1:$C$15000,B18,INFO.RENTABILIDAD!$W$1:$W$15000,"SI") -> 2130000 | G18: =SUMIFS(INFO.RENTABILIDAD!$L$1:$L$999,INFO.RENTABILIDAD!$C$1:$C$999,B18,INFO.RENTABILIDAD!$W$1:$W$999,"NO") -> 0 | H18: =SUMIFS(INFO.RENTABILIDAD!$L$1:$L$999,INFO.RENTABILIDAD!$C$1:$C$999,B18,INFO.RENTABILIDAD!$W$1:$W$999,"SIN PAGO") -> 0 | I18: =SUMIF(INFO.RENTABILIDAD!C:C,B18,INFO.RENTABILIDAD!L:L) -> 2130000 | J18: - | L18: ='BALANCE PPTO'!D10 -> % DIFERENCIA | M18: ='BALANCE PPTO'!E10 -> NOS FALTA VENDER
B19: 46069 | C19: 0 | D19: 0 | E19: =SUMIF(INFO.PROYECCIÓN!$C:$C,B19,INFO.PROYECCIÓN!$L:$L) -> 0 | F19: =SUMIFS(INFO.RENTABILIDAD!$L$1:$L$15000,INFO.RENTABILIDAD!$C$1:$C$15000,B19,INFO.RENTABILIDAD!$W$1:$W$15000,"SI") -> 26208000 | G19: =SUMIFS(INFO.RENTABILIDAD!$L$1:$L$999,INFO.RENTABILIDAD!$C$1:$C$999,B19,INFO.RENTABILIDAD!$W$1:$W$999,"NO") -> 0 | H19: =SUMIFS(INFO.RENTABILIDAD!$L$1:$L$999,INFO.RENTABILIDAD!$C$1:$C$999,B19,INFO.RENTABILIDAD!$W$1:$W$999,"SIN PAGO") -> 0 | I19: =SUMIF(INFO.RENTABILIDAD!C:C,B19,INFO.RENTABILIDAD!L:L) -> 26208000 | J19: - | L19: ='BALANCE PPTO'!D11 -> -0.076864744 | M19: ='BALANCE PPTO'!E11 -> 0.41019808
